Failure # 1 (occurred at 2021-09-18_16-10-11)
Traceback (most recent call last):
  File "/Users/reedpan/opt/anaconda3/envs/rl/lib/python3.9/site-packages/ray/tune/trial_runner.py", line 739, in _process_trial
    results = self.trial_executor.fetch_result(trial)
  File "/Users/reedpan/opt/anaconda3/envs/rl/lib/python3.9/site-packages/ray/tune/ray_trial_executor.py", line 746, in fetch_result
    result = ray.get(trial_future[0], timeout=DEFAULT_GET_TIMEOUT)
  File "/Users/reedpan/opt/anaconda3/envs/rl/lib/python3.9/site-packages/ray/_private/client_mode_hook.py", line 82, in wrapper
    return func(*args, **kwargs)
  File "/Users/reedpan/opt/anaconda3/envs/rl/lib/python3.9/site-packages/ray/worker.py", line 1623, in get
    raise value
ray.exceptions.RayActorError: The actor died because of an error raised in its creation task, [36mray::MADDPG.__init__()[39m (pid=76723, ip=183.173.48.48)
  File "/Users/reedpan/opt/anaconda3/envs/rl/lib/python3.9/site-packages/ray/rllib/agents/trainer_template.py", line 136, in __init__
    Trainer.__init__(self, config, env, logger_creator)
  File "/Users/reedpan/opt/anaconda3/envs/rl/lib/python3.9/site-packages/ray/rllib/agents/trainer.py", line 592, in __init__
    super().__init__(config, logger_creator)
  File "/Users/reedpan/opt/anaconda3/envs/rl/lib/python3.9/site-packages/ray/tune/trainable.py", line 103, in __init__
    self.setup(copy.deepcopy(self.config))
  File "/Users/reedpan/opt/anaconda3/envs/rl/lib/python3.9/site-packages/ray/rllib/agents/trainer_template.py", line 146, in setup
    super().setup(config)
  File "/Users/reedpan/opt/anaconda3/envs/rl/lib/python3.9/site-packages/ray/rllib/agents/trainer.py", line 739, in setup
    self._init(self.config, self.env_creator)
  File "/Users/reedpan/opt/anaconda3/envs/rl/lib/python3.9/site-packages/ray/rllib/agents/trainer_template.py", line 170, in _init
    self.workers = self._make_workers(
  File "/Users/reedpan/opt/anaconda3/envs/rl/lib/python3.9/site-packages/ray/rllib/agents/trainer.py", line 821, in _make_workers
    return WorkerSet(
  File "/Users/reedpan/opt/anaconda3/envs/rl/lib/python3.9/site-packages/ray/rllib/evaluation/worker_set.py", line 83, in __init__
    remote_spaces = ray.get(self.remote_workers(
ray.exceptions.RayActorError: The actor died because of an error raised in its creation task, [36mray::RolloutWorker.__init__()[39m (pid=76722, ip=183.173.48.48)
  File "/Users/reedpan/opt/anaconda3/envs/rl/lib/python3.9/site-packages/ray/rllib/evaluation/rollout_worker.py", line 580, in __init__
    self._build_policy_map(
  File "/Users/reedpan/opt/anaconda3/envs/rl/lib/python3.9/site-packages/ray/rllib/evaluation/rollout_worker.py", line 1375, in _build_policy_map
    self.policy_map.create_policy(name, orig_cls, obs_space, act_space,
  File "/Users/reedpan/opt/anaconda3/envs/rl/lib/python3.9/site-packages/ray/rllib/policy/policy_map.py", line 126, in create_policy
    self[policy_id] = class_(
  File "/Users/reedpan/opt/anaconda3/envs/rl/lib/python3.9/site-packages/ray/rllib/contrib/maddpg/maddpg_policy.py", line 150, in __init__
    self._build_actor_network(
  File "/Users/reedpan/opt/anaconda3/envs/rl/lib/python3.9/site-packages/ray/rllib/contrib/maddpg/maddpg_policy.py", line 374, in _build_actor_network
    sampler = tfp.distributions.RelaxedOneHotCategorical(
AttributeError: 'NoneType' object has no attribute 'distributions'

