Failure # 1 (occurred at 2021-09-18_16-00-39)
Traceback (most recent call last):
  File "/Users/reedpan/opt/anaconda3/envs/rl/lib/python3.9/site-packages/ray/tune/trial_runner.py", line 739, in _process_trial
    results = self.trial_executor.fetch_result(trial)
  File "/Users/reedpan/opt/anaconda3/envs/rl/lib/python3.9/site-packages/ray/tune/ray_trial_executor.py", line 746, in fetch_result
    result = ray.get(trial_future[0], timeout=DEFAULT_GET_TIMEOUT)
  File "/Users/reedpan/opt/anaconda3/envs/rl/lib/python3.9/site-packages/ray/_private/client_mode_hook.py", line 82, in wrapper
    return func(*args, **kwargs)
  File "/Users/reedpan/opt/anaconda3/envs/rl/lib/python3.9/site-packages/ray/worker.py", line 1623, in get
    raise value
ray.exceptions.RayActorError: The actor died because of an error raised in its creation task, [36mray::MADDPG.__init__()[39m (pid=75298, ip=183.173.48.48)
  File "/Users/reedpan/opt/anaconda3/envs/rl/lib/python3.9/site-packages/ray/rllib/agents/trainer_template.py", line 136, in __init__
    Trainer.__init__(self, config, env, logger_creator)
  File "/Users/reedpan/opt/anaconda3/envs/rl/lib/python3.9/site-packages/ray/rllib/agents/trainer.py", line 592, in __init__
    super().__init__(config, logger_creator)
  File "/Users/reedpan/opt/anaconda3/envs/rl/lib/python3.9/site-packages/ray/tune/trainable.py", line 103, in __init__
    self.setup(copy.deepcopy(self.config))
  File "/Users/reedpan/opt/anaconda3/envs/rl/lib/python3.9/site-packages/ray/rllib/agents/trainer_template.py", line 146, in setup
    super().setup(config)
  File "/Users/reedpan/opt/anaconda3/envs/rl/lib/python3.9/site-packages/ray/rllib/agents/trainer.py", line 700, in setup
    self.config = self.merge_trainer_configs(self._default_config, config,
  File "/Users/reedpan/opt/anaconda3/envs/rl/lib/python3.9/site-packages/ray/rllib/agents/trainer.py", line 1357, in merge_trainer_configs
    return deep_update(config1, config2, _allow_unknown_configs,
  File "/Users/reedpan/opt/anaconda3/envs/rl/lib/python3.9/site-packages/ray/tune/utils/util.py", line 264, in deep_update
    raise Exception("Unknown config parameter `{}` ".format(k))
Exception: Unknown config parameter `sample_batch_size`

